<?xml version="1.0"?>
<robot name="robot_car">
        <link name="base_footprint">
                
        </link>
        <joint name="base_joint" type="fixed">
                <origin xyz="0.0 0.0 0.2" rpy="0.0 0.0 0.0"/>
                <parent link="base_footprint"/>
                <child link="base_link"/>
        </joint>
        <link name="base_link">
                <inertial>
                        <origin xyz="0.0 0.0 0.0" rpy="0.0 0.0 0.0"/>
                        <mass value="10.0"/>
                        <inertia ixx="1.0" ixy="0.0" ixz="0.0" iyy="1.0" iyz="0.0" izz="1.0"/>
                </inertial>
                <visual name="">
                        <origin xyz="0.0 0.0 0.0" rpy="0.0 0.0 0.0"/>
                        <geometry>
                                <box size="0.6 0.4 0.2"/>
                        </geometry>
                        <material name="">
                                <color rgba="1.0 0.0 0.0 0.2"/>
                                <texture filename=""/>
                        </material>
                </visual>
                <collision>
                        <origin xyz="0.0 0.0 0.0" rpy="0.0 0.0 0.0"/>
                        <geometry>
                                <box size="0.6 0.4 0.2"/>
                        </geometry>
                </collision>
        </link>

        <link name="fl_wheel_link">
                <inertial>
                        <origin xyz="0.0 0.0 0.0" rpy="0.0 0.0 0.0"/>
                        <mass value="1.0"/>
                        <inertia ixx="1.0" ixy="0.0" ixz="0.0" iyy="1.0" iyz="0.0" izz="1.0"/>
                </inertial>
                <visual name="">
                        <origin xyz="0.0 0.0 0.0" rpy="0.0 0.0 0.0"/>
                        <geometry>
                                <cylinder radius="0.08" length="0.04"/>
                        </geometry>
                        <material name="">
                                <color rgba="1.0 0.0 0.0 1.0"/>
                                <texture filename=""/>
                        </material>
                </visual>
                <collision>
                        <origin xyz="0.0 0.0 0.0" rpy="0 0.0 0.0"/>
                        <geometry>
                                <cylinder radius="0.08" length="0.04"/>
                        </geometry>
                </collision>
        </link>

        <joint name="fl_wheel_joint" type="continuous">
                <origin xyz="0.22 0.22 -0.1" rpy="1.57 0.0 0.0"/>
                <parent link="base_link"/>
                <child link="fl_wheel_link"/>
                <axis xyz="0.0 0.0 -1.0"/>
                <limit effort="100.0" velocity="10.0"/>
        </joint>


        <link name="fr_wheel_link">
                <inertial>
                        <origin xyz="0.0 0.0 0.0" rpy="0.0 0.0 0.0"/>
                        <mass value="1.0"/>
                        <inertia ixx="1.0" ixy="0.0" ixz="0.0" iyy="1.0" iyz="0.0" izz="1.0"/>
                </inertial>
                <visual name="">
                        <origin xyz="0.0 0.0 0.0" rpy="0.0 0.0 0.0"/>
                        <geometry>
                                <cylinder radius="0.08" length="0.04"/>
                        </geometry>
                        <material name="">
                                <color rgba="1.0 0.0 0.0 1.0"/>
                                <texture filename=""/>
                        </material>
                </visual>
                <collision>
                        <origin xyz="0.0 0.0 0.0" rpy="0 0.0 0.0"/>
                        <geometry>
                                <cylinder radius="0.08" length="0.04"/>
                        </geometry>
                </collision>
        </link>

        <joint name="fr_wheel_joint" type="continuous">
                <origin xyz="0.22 -0.22 -0.1" rpy="1.57 0.0 0.0"/>
                <parent link="base_link"/>
                <child link="fr_wheel_link"/>
                <axis xyz="0.0 0.0 -1.0"/>
                <limit effort="100.0" velocity="10.0"/>
        </joint>

        <link name="bl_wheel_link">
                <inertial>
                        <origin xyz="0.0 0.0 0.0" rpy="0.0 0.0 0.0"/>
                        <mass value="1.0"/>
                        <inertia ixx="1.0" ixy="0.0" ixz="0.0" iyy="1.0" iyz="0.0" izz="1.0"/>
                </inertial>
                <visual name="">
                        <origin xyz="0.0 0.0 0.0" rpy="0.0 0.0 0.0"/>
                        <geometry>
                                <cylinder radius="0.08" length="0.04"/>
                        </geometry>
                        <material name="">
                                <color rgba="1.0 0.0 0.0 1.0"/>
                                <texture filename=""/>
                        </material>
                </visual>
                <collision>
                        <origin xyz="0.0 0.0 0.0" rpy="0 0.0 0.0"/>
                        <geometry>
                                <cylinder radius="0.08" length="0.04"/>
                        </geometry>
                </collision>
        </link>

        <joint name="bl_wheel_joint" type="continuous">
                <origin xyz="-0.22 0.22 -0.1" rpy="1.57 0.0 0.0"/>
                <parent link="base_link"/>
                <child link="bl_wheel_link"/>
                <axis xyz="0.0 0.0 -1.0"/>
        </joint>

        <link name="br_wheel_link">
                <inertial>
                        <origin xyz="0.0 0.0 0.0" rpy="0.0 0.0 0.0"/>
                        <mass value="1.0"/>
                        <inertia ixx="1.0" ixy="0.0" ixz="0.0" iyy="1.0" iyz="0.0" izz="1.0"/>
                </inertial>
                <visual name="">
                        <origin xyz="0.0 0.0 0.0" rpy="0.0 0.0 0.0"/>
                        <geometry>
                                <cylinder radius="0.08" length="0.04"/>
                        </geometry>
                        <material name="">
                                <color rgba="1.0 0.0 0.0 1.0"/>
                                <texture filename=""/>
                        </material>
                </visual>
                <collision>
                        <origin xyz="0.0 0.0 0.0" rpy="0 0.0 0.0"/>
                        <geometry>
                                <cylinder radius="0.08" length="0.04"/>
                        </geometry>
                </collision>
        </link>

        <joint name="br_wheel_joint" type="continuous">
                <origin xyz="-0.22 -0.22 -0.1" rpy="1.57 0.0 0.0"/>
                <parent link="base_link"/>
                <child link="br_wheel_link"/>
                <axis xyz="0.0 0.0 -1.0"/>
        </joint>

        <gazebo reference="base_link">
                <material>Gazebo/Red</material>
                <selfCollide>false</selfCollide>
                <mu1 value="2.0"/>
                <mu2 value="2.0"/>
        </gazebo>

        <gazebo reference="fl_wheel_link">
                <material>Gazebo/Black</material>
                <selfCollide>false</selfCollide>
                <mu1 value="2.0"/>
                <mu2 value="2.0"/>
        </gazebo>

        <gazebo reference="fr_wheel_link">
                <material>Gazebo/Black</material>
                <selfCollide>false</selfCollide>
                <mu1 value="2.0"/>
                <mu2 value="2.0"/>
        </gazebo>

        <gazebo reference="bl_wheel_link">
                <material>Gazebo/Black</material>
                <selfCollide>false</selfCollide>
                <mu1 value="2.0"/>
                <mu2 value="2.0"/>
        </gazebo>

        <gazebo reference="br_wheel_link">
                <material>Gazebo/Black</material>
        </gazebo>


        <transmission name="fl_wheel_trans">
                <type>transmission_interface/SimpleTransmission</type>
                <joint name="fl_wheel_joint">
                        <hardwareInterface>hardware_interface/VelocityJointInterface</hardwareInterface>
                </joint>
                <actuator name="fl_wheel_motor">
                        <mechanicalReduction>1.0</mechanicalReduction>
                        <hardwareInterface>hardware_interface/VelocityJointInterface</hardwareInterface>
                </actuator>
        </transmission>

        <transmission name="fr_wheel_trans">
                <type>transmission_interface/SimpleTransmission</type>
                <joint name="fr_wheel_joint">
                        <hardwareInterface>hardware_interface/VelocityJointInterface</hardwareInterface>
                </joint>
                <actuator name="flrwheel_motor">
                        <mechanicalReduction>1.0</mechanicalReduction>
                        <hardwareInterface>hardware_interface/VelocityJointInterface</hardwareInterface>
                </actuator>
        </transmission>


        <gazebo>
                <plugin name="gazebo_ros_control" filename="libgazebo_ros_control.so">
                </plugin>
                <plugin name="differ" filename="libgazebo_ros_diff_drive.so">
                        <alwaysOn>true</alwaysOn>
                        <updateRate>100</updateRate>
                        <leftJoint>fl_wheel_joint</leftJoint>
                        <rightJoint>fr_wheel_joint</rightJoint>
                        <wheelSeparation>0.44</wheelSeparation>
                        <wheelDiameter>1</wheelDiameter>
                        <wheelAcceleration>1.0</wheelAcceleration>
                        <wheelTorque>100</wheelTorque>
                        <commandTopic>cmd_vel</commandTopic>
                        <odometryTopic>odom</odometryTopic>
                        <odometryFrame>odom</odometryFrame>
                        <robotBaseFrame>base_footprint</robotBaseFrame>
                        <odometrySource>0</odometrySource>
                        <publishWheelTF>true</publishWheelTF>
                        <publishOdom>true</publishOdom>
                        <publishWheelJointState>true</publishWheelJointState>
                        <legacyMode>false</legacyMode>
                        <rosDebugLevel>true</rosDebugLevel>
                </plugin>
        </gazebo>

        <plugin name="ground_truth_odometry" filename="libgazebo_ros_p3d.so">
                <alwaysOn>true</alwaysOn>
                <updateRate>100.0</updateRate>
                <bodyName>base_footprint</bodyName>
                <topicName>robot_pose</topicName>
                <gaussianNoise>0.01</gaussianNoise>
                <frameName>world</frameName>
                <xyzOffsets>0 0 0</xyzOffsets>
                <rpyOffsets>0 0 0</rpyOffsets>
        </plugin>


</robot>